<?xml version="1.0" ?>
<!-- =================================================================================== -->
<!-- |    This document was autogenerated by xacro from laelaps.xacro                  | -->
<!-- |    EDITING THIS FILE BY HAND IS NOT RECOMMENDED                                 | -->
<!-- =================================================================================== -->
<!-- =================================================================================== -->
<!-- |    This document was autogenerated by xacro from laelaps_robot.urdf.xacro        | -->
<!-- |    EDITING THIS FILE BY HAND IS NOT RECOMMENDED                                 | -->
<!-- =================================================================================== -->
<!--
This file includes the main robot description of the new developed by CSL at NTUA Athens
-->
<robot name="laelaps_robot">
  <mujoco>
        <compiler
        balanceinertia="true"
        discardvisual="false" />
  </mujoco>
  <link name="initial_link"/>
  <joint name="floating_base" type="fixed">
    <parent link="initial_link"/>
    <child link="body"/>
  </joint>
  <!-- base -->
  <link name="body">
    <collision>
      <origin rpy="0 0 0" xyz="-0.01 0 0.6"/>
      <geometry>
        <mesh filename="body200000.stl"/>
      </geometry>
    </collision>
    <visual>
      <origin rpy="1.57 0 0" xyz="-0.01 0 0.6"/>
      <geometry>
        <mesh filename="body200000.stl"/>
      </geometry>
    </visual>
    <inertial>
      <origin rpy="0 0 0" xyz="-0.01 0 0.6"/>
      <mass value="40"/>
      <inertia ixx="0.87" ixy="0.0" ixz="0.0" iyy="1.23" iyz="0.0" izz="2.03"/>
    </inertial>
  </link>
  <!-- arm -->
  <!-- arm -->
  <!-- arm -->
  <link name="RF_arm">
    <collision>
      <origin rpy="0 0 0" xyz="0 0 0"/>
      <geometry>
        <mesh filename="transmission_arm.STL"/>
      </geometry>
    </collision>
    <visual>
      <origin rpy="0 0 0" xyz="0 0 0"/>
      <geometry>
        <mesh filename="transmission_arm.STL"/>
      </geometry>
    </visual>
    <inertial>
      <origin rpy="0.0 0.0 0" xyz="0.001841 0.001845 0.000604"/>
      <mass value="0.243583"/>
      <inertia ixx="0.000238" ixy="-0.000143" ixz="0" iyy="0.000238" iyz="0" izz="0.000326"/>
    </inertial>
  </link>
  <!-- upper leg -->
  <!-- upper leg -->
  <!-- upper leg -->
  <link name="RF_femur">
    <collision>
      <origin rpy="0 0 0" xyz="0 0 0"/>
      <geometry>
        <mesh filename="femur.STL"/>
      </geometry>
    </collision>
    <visual>
      <origin rpy="0 0 0" xyz="0 0 0"/>
      <geometry>
        <mesh filename="femur.STL"/>
      </geometry>
    </visual>
    <inertial>
      <origin rpy="0 0 0" xyz="0 -0.1089928 0.0013804"/>
      <mass value="0.321675"/>
      <inertia ixx="0.0030216" ixy="0.0" ixz="0.0" iyy="6.06e-05" iyz="5.08e-05" izz="0.0030174"/>
    </inertial>
  </link>
  <!-- lower leg -->
  <!-- lower leg -->
  <!-- lower leg -->
  <link name="RF_tibia">
    <collision>
      <origin rpy="0 0 0" xyz="0 0 0"/>
      <geometry>
        <mesh filename="tibia.STL"/>
      </geometry>
    </collision>
    <visual>
      <origin rpy="0 0 0" xyz="0 0 0"/>
      <geometry>
        <mesh filename="tibia.STL"/>
      </geometry>
    </visual>
    <inertial>
      <origin rpy="0.0 0.0 0" xyz="0.0343235 -0.1131727 -0.0003377"/>
      <mass value="0.583068"/>
      <inertia ixx="0.0069971" ixy="-0.0025079" ixz="-4.13e-05" iyy="0.00113" iyz="0.0001357" izz="0.0080248"/>
    </inertial>
  </link>
  <!-- foot -->
  <!-- foot -->
  <!-- foot -->
  <link name="RF_foot">
    <collision>
      <origin rpy="0 0 0" xyz="0 0 0"/>
      <geometry>
        <mesh filename="foot.STL"/>
      </geometry>
    </collision>
    <visual>
      <origin rpy="0 0 0" xyz="0 0 0"/>
      <geometry>
        <mesh filename="foot.STL"/>
      </geometry>
    </visual>
    <inertial>
      <origin rpy="0 0 0" xyz="0 0 0"/>
      <mass value="0.185259"/>
      <inertia ixx="3.9e-05" ixy="0.000114" ixz="1.4e-05" iyy="0.000946" iyz="3e-06" izz="0.000974"/>
    </inertial>
  </link>
  <!-- foot -->
  <!-- foot -->
  <!-- foot -->
  <gazebo reference="RF_foot">
    <collision>
      <surface>
        <bounce>
          <restitution_coefficient>0</restitution_coefficient>
          <threshold>1e+06</threshold>
        </bounce>
        <friction>
          <torsional>
            <coefficient>1.0</coefficient>
          </torsional>
          <ode>
            <mu>1.2</mu>
            <mu2>1.2</mu2>
          </ode>
          <bullet>
            <rolling_friction>1.0</rolling_friction>
            <friction2>1.2</friction2>
          </bullet>
        </friction>
        <contact>
          <ode>
            <kp>300000.0</kp>
            <kd>1000.0</kd>
          </ode>
          <bullet>
            <kp>300000.0</kp>
            <kd>1000.0</kd>
          </bullet>
        </contact>
      </surface>
    </collision>
  </gazebo>
  <!-- cable -->
  <!-- cable -->
  <!-- cable -->
  <link name="RF_cable">
    <collision>
      <origin rpy="0 0 0" xyz="0 0 0"/>
      <geometry>
        <mesh filename="cable.STL"/>
      </geometry>
    </collision>
    <visual>
      <origin rpy="0 0 0" xyz="0 0 0"/>
      <geometry>
        <mesh filename="cable.STL"/>
      </geometry>
    </visual>
    <inertial>
      <origin rpy="0 0 0" xyz="0 -0.125 0"/>
      <mass value="0.1"/>
      <inertia ixx="8e-05" ixy="0" ixz="0" iyy="2e-06" iyz="0.0" izz="8e-05"/>
    </inertial>
  </link>
  <!-- spring_part_a -->
  <!-- spring_part_a -->
  <!-- spring_part_a -->
  <link name="RF_spring_part_a">
    <collision>
      <origin rpy="0 0 0" xyz="0 0 0"/>
      <geometry>
        <mesh filename="spring_part_a.STL"/>
      </geometry>
    </collision>
    <visual>
      <origin rpy="0 0 0" xyz="0 0 0"/>
      <geometry>
        <mesh filename="spring_part_a.STL"/>
      </geometry>
    </visual>
    <inertial>
      <origin rpy="0 0 0" xyz="0 0 0"/>
      <mass value="0.05"/>
      <inertia ixx="1.2e-05" ixy="0" ixz="0" iyy="6.06e-05" iyz="5.08e-05" izz="0.0030174"/>
    </inertial>
  </link>
  <!-- spring_part_b -->
  <!-- spring_part_b -->
  <!-- spring_part_b -->
  <link name="RF_spring_part_b">
    <collision>
      <origin rpy="0 0 0" xyz="0 -0.03 0"/>
      <geometry>
        <mesh filename="spring_part_b.STL"/>
      </geometry>
    </collision>
    <visual>
      <origin rpy="0 0 0" xyz="0 -0.03 0"/>
      <geometry>
        <mesh filename="spring_part_b.STL"/>
      </geometry>
    </visual>
    <inertial>
      <origin rpy="0 0 0" xyz="0 0 0"/>
      <mass value="0.05"/>
      <inertia ixx="1.2e-05" ixy="0" ixz="0" iyy="1e-06" iyz="0" izz="1.2e-05"/>
    </inertial>
  </link>
  <!-- joint A -->
  <!-- joint A -->
  <!-- joint A -->
  <joint name="RF_joint_knee" type="revolute">
    <origin rpy="1.57 0 0" xyz="-0.3 0.2 0.6"/>
    <parent link="body"/>
    <child link="RF_arm"/>
    <axis xyz="0 0 1"/>
    <dynamics damping="0.0"/>
    <limit effort="50" lower="-1.25" upper="1.25" velocity="8"/>
  </joint>
  <!-- joint B -->
  <!-- joint B -->
  <!-- joint B -->
  <joint name="RF_joint_hip" type="revolute">
    <origin rpy="1.57 0 0" xyz="-0.3 0.184 0.6"/>
    <parent link="body"/>
    <child link="RF_femur"/>
    <axis xyz="0 0 1"/>
    <dynamics damping="0.0"/>
    <limit effort="50" lower="-1.25" upper="1.25" velocity="6"/>
  </joint>
  <!-- joint C -->
  <!-- joint C -->
  <!-- joint C -->
  <joint name="RF_joint_C" type="revolute">
    <origin rpy="0 0 0" xyz="0 -0.25 0"/>
    <parent link="RF_femur"/>
    <child link="RF_tibia"/>
    <axis xyz="0 0 1"/>
    <dynamics damping="0.0"/>
    <limit effort="100" lower="0.0" upper="1.57" velocity="100"/>
  </joint>
  <!-- joint D -->
  <!-- joint D -->
  <!-- joint D -->
  <joint name="RF_joint_D" type="revolute">
    <origin rpy="0 0 0.317475" xyz="0.09958 -0.3 0"/>
    <parent link="RF_tibia"/>
    <child link="RF_foot"/>
    <axis xyz="0 0 1"/>
    <dynamics damping="0.0"/>
    <limit effort="100" lower="-1.25" upper="1.25" velocity="100"/>
  </joint>
  <!-- joint E -->
  <!-- joint E -->
  <!-- joint E -->
  <joint name="RF_joint_E" type="continuous">
    <origin rpy="0 0 0" xyz="0.03536 -0.03536 0.0246"/>
    <parent link="RF_arm"/>
    <child link="RF_cable"/>
    <axis xyz="0 0 1"/>
    <dynamics damping="0.0"/>
    <limit effort="100" velocity="100"/>
  </joint>
  <!-- joint F -->
  <!-- joint F -->
  <!-- joint F -->
  <joint name="RF_joint_F" type="continuous">
    <origin rpy="0 0 0.608596" xyz="0.0514 -0.06 0.0089"/>
    <parent link="RF_tibia"/>
    <child link="RF_spring_part_a"/>
    <axis xyz="0 0 1"/>
    <dynamics damping="0.0"/>
    <limit effort="100" velocity="100"/>
  </joint>
  <!-- joint G -->
  <!-- joint G -->
  <!-- joint G -->
  <joint name="RF_joint_G" type="prismatic">
    <origin rpy="0 0 0" xyz="-0 -0.2 0"/>
    <parent link="RF_spring_part_a"/>
    <child link="RF_spring_part_b"/>
    <axis xyz="0 1 0"/>
    <dynamics damping="0.0"/>
    <limit effort="0" lower="-0.05" upper="0" velocity="0"/>
  </joint>
  <!-- joint G SDF -->
  <!-- joint G SDF -->
  <!-- joint G SDF -->
  <gazebo>
    <joint name="RF_joint_G_SDF" type="prismatic">
      <parent>RF_spring_part_a</parent>
      <child>RF_spring_part_b</child>
      <pose frame="">0 0 0 0 -0 0</pose>
      <axis>
        <xyz>0 1 0</xyz>
        <use_parent_model_frame>1</use_parent_model_frame>
        <limit>
          <lower>-0.05</lower>
          <upper>0</upper>
          <effort>0</effort>
          <velocity>0</velocity>
        </limit>
        <dynamics>
          <spring_reference>0</spring_reference>
          <spring_stiffness>26480</spring_stiffness>
          <damping>0.1</damping>
          <friction>0</friction>
        </dynamics>
      </axis>
    </joint>
  </gazebo>
  <!-- Gazebo Joint GA1  -->
  <!-- Gazebo Joint GA1  -->
  <!-- Gazebo Joint GA1  -->
  <gazebo>
    <joint name="RF_joint_GA1" type="revolute">
      <pose>0 -0.25 0 0 0 0</pose>
      <child>RF_cable</child>
      <parent>RF_tibia</parent>
      <axis>
        <xyz>0 0 1</xyz>
      </axis>
      <physics>
        <ode>
          <erp>0.5</erp>
          <!-- <cfm>0.1</cfm> -->
        </ode>
      </physics>
    </joint>
  </gazebo>
  <!-- Gazebo Joint GA2  -->
  <!-- Gazebo Joint GA2  -->
  <!-- Gazebo Joint GA2  -->
  <gazebo>
    <joint name="RF_joint_GA2" type="revolute">
      <pose>0 -0.025 0 0 0 0</pose>
      <child>RF_spring_part_b</child>
      <parent>RF_foot</parent>
      <axis>
        <xyz>0 0 1</xyz>
      </axis>
    </joint>
  </gazebo>
  <!-- Gazebo sensor A -->
  <!-- Gazebo sensor A -->
  <!-- Gazebo sensor A -->
  <gazebo reference="RF_joint_knee">
    <sensor name="RF_force_torque" type="force_torque">
      <always_on>true</always_on>
      <update_rate>1000</update_rate>
    </sensor>
  </gazebo>
  <!-- Gazebo sensor B -->
  <!-- Gazebo sensor B -->
  <!-- Gazebo sensor B -->
  <gazebo reference="RF_joint_hip">
    <sensor name="RF_force_torque" type="force_torque">
      <always_on>true</always_on>
      <update_rate>1000</update_rate>
    </sensor>
  </gazebo>
  <!-- Gazebo foot  -->
  <!-- Gazebo foot  -->
  <!-- Gazebo foot  -->
  <!-- <gazebo reference="${prefix1}${prefix2}_foot">
            <kp>100000</kp>
            <mu1>10</mu1>
            <mu2>10</mu2>
        </gazebo> -->
  <!-- Gazebo Joint TRAN1  -->
  <!-- Gazebo Joint TRAN1  -->
  <!-- Gazebo Joint TRAN1  -->
  <transmission name="RF_tran1">
    <type>transmission_interface/SimpleTransmission</type>
    <joint name="RF_joint_knee">
      <hardwareInterface>hardware_interface/EffortJointInterface</hardwareInterface>
    </joint>
    <actuator name="RF_motor1">
      <hardwareInterface>hardware_interface/EffortJointInterface</hardwareInterface>
      <mechanicalReduction>1</mechanicalReduction>
    </actuator>
  </transmission>
  <!-- Gazebo Joint TRAN2  -->
  <!-- Gazebo Joint TRAN2  -->
  <!-- Gazebo Joint TRAN2  -->
  <transmission name="RF_tran2">
    <type>transmission_interface/SimpleTransmission</type>
    <joint name="RF_joint_hip">
      <hardwareInterface>hardware_interface/EffortJointInterface</hardwareInterface>
    </joint>
    <actuator name="RF_motor2">
      <hardwareInterface>hardware_interface/EffortJointInterface</hardwareInterface>
      <mechanicalReduction>1</mechanicalReduction>
    </actuator>
  </transmission>
  <!-- arm -->
  <!-- arm -->
  <!-- arm -->
  <link name="RH_arm">
    <collision>
      <origin rpy="0 0 0" xyz="0 0 0"/>
      <geometry>
        <mesh filename="transmission_arm.STL"/>
      </geometry>
    </collision>
    <visual>
      <origin rpy="0 0 0" xyz="0 0 0"/>
      <geometry>
        <mesh filename="transmission_arm.STL"/>
      </geometry>
    </visual>
    <inertial>
      <origin rpy="0.0 0.0 0" xyz="0.001841 0.001845 0.000604"/>
      <mass value="0.243583"/>
      <inertia ixx="0.000238" ixy="-0.000143" ixz="0" iyy="0.000238" iyz="0" izz="0.000326"/>
    </inertial>
  </link>
  <!-- upper leg -->
  <!-- upper leg -->
  <!-- upper leg -->
  <link name="RH_femur">
    <collision>
      <origin rpy="0 0 0" xyz="0 0 0"/>
      <geometry>
        <mesh filename="femur.STL"/>
      </geometry>
    </collision>
    <visual>
      <origin rpy="0 0 0" xyz="0 0 0"/>
      <geometry>
        <mesh filename="femur.STL"/>
      </geometry>
    </visual>
    <inertial>
      <origin rpy="0 0 0" xyz="0 -0.1089928 0.0013804"/>
      <mass value="0.321675"/>
      <inertia ixx="0.0030216" ixy="0.0" ixz="0.0" iyy="6.06e-05" iyz="5.08e-05" izz="0.0030174"/>
    </inertial>
  </link>
  <!-- lower leg -->
  <!-- lower leg -->
  <!-- lower leg -->
  <link name="RH_tibia">
    <collision>
      <origin rpy="0 0 0" xyz="0 0 0"/>
      <geometry>
        <mesh filename="tibia.STL"/>
      </geometry>
    </collision>
    <visual>
      <origin rpy="0 0 0" xyz="0 0 0"/>
      <geometry>
        <mesh filename="tibia.STL"/>
      </geometry>
    </visual>
    <inertial>
      <origin rpy="0.0 0.0 0" xyz="0.0343235 -0.1131727 -0.0003377"/>
      <mass value="0.583068"/>
      <inertia ixx="0.0069971" ixy="-0.0025079" ixz="-4.13e-05" iyy="0.00113" iyz="0.0001357" izz="0.0080248"/>
    </inertial>
  </link>
  <!-- foot -->
  <!-- foot -->
  <!-- foot -->
  <link name="RH_foot">
    <collision>
      <origin rpy="0 0 0" xyz="0 0 0"/>
      <geometry>
        <mesh filename="foot.STL"/>
      </geometry>
    </collision>
    <visual>
      <origin rpy="0 0 0" xyz="0 0 0"/>
      <geometry>
        <mesh filename="foot.STL"/>
      </geometry>
    </visual>
    <inertial>
      <origin rpy="0 0 0" xyz="0 0 0"/>
      <mass value="0.185259"/>
      <inertia ixx="3.9e-05" ixy="0.000114" ixz="1.4e-05" iyy="0.000946" iyz="3e-06" izz="0.000974"/>
    </inertial>
  </link>
  <!-- foot -->
  <!-- foot -->
  <!-- foot -->
  <gazebo reference="RH_foot">
    <collision>
      <surface>
        <bounce>
          <restitution_coefficient>0</restitution_coefficient>
          <threshold>1e+06</threshold>
        </bounce>
        <friction>
          <torsional>
            <coefficient>1.0</coefficient>
          </torsional>
          <ode>
            <mu>1.2</mu>
            <mu2>1.2</mu2>
          </ode>
          <bullet>
            <rolling_friction>1.0</rolling_friction>
            <friction2>1.2</friction2>
          </bullet>
        </friction>
        <contact>
          <ode>
            <kp>300000.0</kp>
            <kd>1000.0</kd>
          </ode>
          <bullet>
            <kp>300000.0</kp>
            <kd>1000.0</kd>
          </bullet>
        </contact>
      </surface>
    </collision>
  </gazebo>
  <!-- cable -->
  <!-- cable -->
  <!-- cable -->
  <link name="RH_cable">
    <collision>
      <origin rpy="0 0 0" xyz="0 0 0"/>
      <geometry>
        <mesh filename="cable.STL"/>
      </geometry>
    </collision>
    <visual>
      <origin rpy="0 0 0" xyz="0 0 0"/>
      <geometry>
        <mesh filename="cable.STL"/>
      </geometry>
    </visual>
    <inertial>
      <origin rpy="0 0 0" xyz="0 -0.125 0"/>
      <mass value="0.1"/>
      <inertia ixx="8e-05" ixy="0" ixz="0" iyy="2e-06" iyz="0.0" izz="8e-05"/>
    </inertial>
  </link>
  <!-- spring_part_a -->
  <!-- spring_part_a -->
  <!-- spring_part_a -->
  <link name="RH_spring_part_a">
    <collision>
      <origin rpy="0 0 0" xyz="0 0 0"/>
      <geometry>
        <mesh filename="spring_part_a.STL"/>
      </geometry>
    </collision>
    <visual>
      <origin rpy="0 0 0" xyz="0 0 0"/>
      <geometry>
        <mesh filename="spring_part_a.STL"/>
      </geometry>
    </visual>
    <inertial>
      <origin rpy="0 0 0" xyz="0 0 0"/>
      <mass value="0.05"/>
      <inertia ixx="1.2e-05" ixy="0" ixz="0" iyy="6.06e-05" iyz="5.08e-05" izz="0.0030174"/>
    </inertial>
  </link>
  <!-- spring_part_b -->
  <!-- spring_part_b -->
  <!-- spring_part_b -->
  <link name="RH_spring_part_b">
    <collision>
      <origin rpy="0 0 0" xyz="0 -0.03 0"/>
      <geometry>
        <mesh filename="spring_part_b.STL"/>
      </geometry>
    </collision>
    <visual>
      <origin rpy="0 0 0" xyz="0 -0.03 0"/>
      <geometry>
        <mesh filename="spring_part_b.STL"/>
      </geometry>
    </visual>
    <inertial>
      <origin rpy="0 0 0" xyz="0 0 0"/>
      <mass value="0.05"/>
      <inertia ixx="1.2e-05" ixy="0" ixz="0" iyy="1e-06" iyz="0" izz="1.2e-05"/>
    </inertial>
  </link>
  <!-- joint A -->
  <!-- joint A -->
  <!-- joint A -->
  <joint name="RH_joint_knee" type="revolute">
    <origin rpy="1.57 0 0" xyz="0.28 0.2 0.6"/>
    <parent link="body"/>
    <child link="RH_arm"/>
    <axis xyz="0 0 1"/>
    <dynamics damping="0.0"/>
    <limit effort="50" lower="-1.25" upper="1.25" velocity="8"/>
  </joint>
  <!-- joint B -->
  <!-- joint B -->
  <!-- joint B -->
  <joint name="RH_joint_hip" type="revolute">
    <origin rpy="1.57 0 0" xyz="0.28 0.184 0.6"/>
    <parent link="body"/>
    <child link="RH_femur"/>
    <axis xyz="0 0 1"/>
    <dynamics damping="0.0"/>
    <limit effort="50" lower="-1.25" upper="1.25" velocity="6"/>
  </joint>
  <!-- joint C -->
  <!-- joint C -->
  <!-- joint C -->
  <joint name="RH_joint_C" type="revolute">
    <origin rpy="0 0 0" xyz="0 -0.25 0"/>
    <parent link="RH_femur"/>
    <child link="RH_tibia"/>
    <axis xyz="0 0 1"/>
    <dynamics damping="0.0"/>
    <limit effort="100" lower="0.0" upper="1.57" velocity="100"/>
  </joint>
  <!-- joint D -->
  <!-- joint D -->
  <!-- joint D -->
  <joint name="RH_joint_D" type="revolute">
    <origin rpy="0 0 0.317475" xyz="0.09958 -0.3 0"/>
    <parent link="RH_tibia"/>
    <child link="RH_foot"/>
    <axis xyz="0 0 1"/>
    <dynamics damping="0.0"/>
    <limit effort="100" lower="-1.25" upper="1.25" velocity="100"/>
  </joint>
  <!-- joint E -->
  <!-- joint E -->
  <!-- joint E -->
  <joint name="RH_joint_E" type="continuous">
    <origin rpy="0 0 0" xyz="0.03536 -0.03536 0.0246"/>
    <parent link="RH_arm"/>
    <child link="RH_cable"/>
    <axis xyz="0 0 1"/>
    <dynamics damping="0.0"/>
    <limit effort="100" velocity="100"/>
  </joint>
  <!-- joint F -->
  <!-- joint F -->
  <!-- joint F -->
  <joint name="RH_joint_F" type="continuous">
    <origin rpy="0 0 0.608596" xyz="0.0514 -0.06 0.0089"/>
    <parent link="RH_tibia"/>
    <child link="RH_spring_part_a"/>
    <axis xyz="0 0 1"/>
    <dynamics damping="0.0"/>
    <limit effort="100" velocity="100"/>
  </joint>
  <!-- joint G -->
  <!-- joint G -->
  <!-- joint G -->
  <joint name="RH_joint_G" type="prismatic">
    <origin rpy="0 0 0" xyz="-0 -0.2 0"/>
    <parent link="RH_spring_part_a"/>
    <child link="RH_spring_part_b"/>
    <axis xyz="0 1 0"/>
    <dynamics damping="0.0"/>
    <limit effort="0" lower="-0.05" upper="0" velocity="0"/>
  </joint>
  <!-- joint G SDF -->
  <!-- joint G SDF -->
  <!-- joint G SDF -->
  <gazebo>
    <joint name="RH_joint_G_SDF" type="prismatic">
      <parent>RH_spring_part_a</parent>
      <child>RH_spring_part_b</child>
      <pose frame="">0 0 0 0 -0 0</pose>
      <axis>
        <xyz>0 1 0</xyz>
        <use_parent_model_frame>1</use_parent_model_frame>
        <limit>
          <lower>-0.05</lower>
          <upper>0</upper>
          <effort>0</effort>
          <velocity>0</velocity>
        </limit>
        <dynamics>
          <spring_reference>0</spring_reference>
          <spring_stiffness>26480</spring_stiffness>
          <damping>0.1</damping>
          <friction>0</friction>
        </dynamics>
      </axis>
    </joint>
  </gazebo>
  <!-- Gazebo Joint GA1  -->
  <!-- Gazebo Joint GA1  -->
  <!-- Gazebo Joint GA1  -->
  <gazebo>
    <joint name="RH_joint_GA1" type="revolute">
      <pose>0 -0.25 0 0 0 0</pose>
      <child>RH_cable</child>
      <parent>RH_tibia</parent>
      <axis>
        <xyz>0 0 1</xyz>
      </axis>
      <physics>
        <ode>
          <erp>0.5</erp>
          <!-- <cfm>0.1</cfm> -->
        </ode>
      </physics>
    </joint>
  </gazebo>
  <!-- Gazebo Joint GA2  -->
  <!-- Gazebo Joint GA2  -->
  <!-- Gazebo Joint GA2  -->
  <gazebo>
    <joint name="RH_joint_GA2" type="revolute">
      <pose>0 -0.025 0 0 0 0</pose>
      <child>RH_spring_part_b</child>
      <parent>RH_foot</parent>
      <axis>
        <xyz>0 0 1</xyz>
      </axis>
    </joint>
  </gazebo>
  <!-- Gazebo sensor A -->
  <!-- Gazebo sensor A -->
  <!-- Gazebo sensor A -->
  <gazebo reference="RH_joint_knee">
    <sensor name="RH_force_torque" type="force_torque">
      <always_on>true</always_on>
      <update_rate>1000</update_rate>
    </sensor>
  </gazebo>
  <!-- Gazebo sensor B -->
  <!-- Gazebo sensor B -->
  <!-- Gazebo sensor B -->
  <gazebo reference="RH_joint_hip">
    <sensor name="RH_force_torque" type="force_torque">
      <always_on>true</always_on>
      <update_rate>1000</update_rate>
    </sensor>
  </gazebo>
  <!-- Gazebo foot  -->
  <!-- Gazebo foot  -->
  <!-- Gazebo foot  -->
  <!-- <gazebo reference="${prefix1}${prefix2}_foot">
            <kp>100000</kp>
            <mu1>10</mu1>
            <mu2>10</mu2>
        </gazebo> -->
  <!-- Gazebo Joint TRAN1  -->
  <!-- Gazebo Joint TRAN1  -->
  <!-- Gazebo Joint TRAN1  -->
  <transmission name="RH_tran1">
    <type>transmission_interface/SimpleTransmission</type>
    <joint name="RH_joint_knee">
      <hardwareInterface>hardware_interface/EffortJointInterface</hardwareInterface>
    </joint>
    <actuator name="RH_motor1">
      <hardwareInterface>hardware_interface/EffortJointInterface</hardwareInterface>
      <mechanicalReduction>1</mechanicalReduction>
    </actuator>
  </transmission>
  <!-- Gazebo Joint TRAN2  -->
  <!-- Gazebo Joint TRAN2  -->
  <!-- Gazebo Joint TRAN2  -->
  <transmission name="RH_tran2">
    <type>transmission_interface/SimpleTransmission</type>
    <joint name="RH_joint_hip">
      <hardwareInterface>hardware_interface/EffortJointInterface</hardwareInterface>
    </joint>
    <actuator name="RH_motor2">
      <hardwareInterface>hardware_interface/EffortJointInterface</hardwareInterface>
      <mechanicalReduction>1</mechanicalReduction>
    </actuator>
  </transmission>
  <!-- arm -->
  <!-- arm -->
  <!-- arm -->
  <link name="LF_arm">
    <collision>
      <origin rpy="0 0 0" xyz="0 0 0"/>
      <geometry>
        <mesh filename="transmission_arm.STL"/>
      </geometry>
    </collision>
    <visual>
      <origin rpy="0 0 0" xyz="0 0 0"/>
      <geometry>
        <mesh filename="transmission_arm.STL"/>
      </geometry>
    </visual>
    <inertial>
      <origin rpy="0.0 0.0 0" xyz="0.001841 0.001845 0.000604"/>
      <mass value="0.243583"/>
      <inertia ixx="0.000238" ixy="-0.000143" ixz="0" iyy="0.000238" iyz="0" izz="0.000326"/>
    </inertial>
  </link>
  <!-- upper leg -->
  <!-- upper leg -->
  <!-- upper leg -->
  <link name="LF_femur">
    <collision>
      <origin rpy="0 0 0" xyz="0 0 0"/>
      <geometry>
        <mesh filename="femur.STL"/>
      </geometry>
    </collision>
    <visual>
      <origin rpy="0 0 0" xyz="0 0 0"/>
      <geometry>
        <mesh filename="femur.STL"/>
      </geometry>
    </visual>
    <inertial>
      <origin rpy="0 0 0" xyz="0 -0.1089928 0.0013804"/>
      <mass value="0.321675"/>
      <inertia ixx="0.0030216" ixy="0.0" ixz="0.0" iyy="6.06e-05" iyz="5.08e-05" izz="0.0030174"/>
    </inertial>
  </link>
  <!-- lower leg -->
  <!-- lower leg -->
  <!-- lower leg -->
  <link name="LF_tibia">
    <collision>
      <origin rpy="0 0 0" xyz="0 0 0"/>
      <geometry>
        <mesh filename="tibia.STL"/>
      </geometry>
    </collision>
    <visual>
      <origin rpy="0 0 0" xyz="0 0 0"/>
      <geometry>
        <mesh filename="tibia.STL"/>
      </geometry>
    </visual>
    <inertial>
      <origin rpy="0.0 0.0 0" xyz="0.0343235 -0.1131727 -0.0003377"/>
      <mass value="0.583068"/>
      <inertia ixx="0.0069971" ixy="-0.0025079" ixz="-4.13e-05" iyy="0.00113" iyz="0.0001357" izz="0.0080248"/>
    </inertial>
  </link>
  <!-- foot -->
  <!-- foot -->
  <!-- foot -->
  <link name="LF_foot">
    <collision>
      <origin rpy="0 0 0" xyz="0 0 0"/>
      <geometry>
        <mesh filename="foot.STL"/>
      </geometry>
    </collision>
    <visual>
      <origin rpy="0 0 0" xyz="0 0 0"/>
      <geometry>
        <mesh filename="foot.STL"/>
      </geometry>
    </visual>
    <inertial>
      <origin rpy="0 0 0" xyz="0 0 0"/>
      <mass value="0.185259"/>
      <inertia ixx="3.9e-05" ixy="0.000114" ixz="1.4e-05" iyy="0.000946" iyz="3e-06" izz="0.000974"/>
    </inertial>
  </link>
  <!-- foot -->
  <!-- foot -->
  <!-- foot -->
  <gazebo reference="LF_foot">
    <collision>
      <surface>
        <bounce>
          <restitution_coefficient>0</restitution_coefficient>
          <threshold>1e+06</threshold>
        </bounce>
        <friction>
          <torsional>
            <coefficient>1.0</coefficient>
          </torsional>
          <ode>
            <mu>1.2</mu>
            <mu2>1.2</mu2>
          </ode>
          <bullet>
            <rolling_friction>1.0</rolling_friction>
            <friction2>1.2</friction2>
          </bullet>
        </friction>
        <contact>
          <ode>
            <kp>300000.0</kp>
            <kd>1000.0</kd>
          </ode>
          <bullet>
            <kp>300000.0</kp>
            <kd>1000.0</kd>
          </bullet>
        </contact>
      </surface>
    </collision>
  </gazebo>
  <!-- cable -->
  <!-- cable -->
  <!-- cable -->
  <link name="LF_cable">
    <collision>
      <origin rpy="0 0 0" xyz="0 0 0"/>
      <geometry>
        <mesh filename="cable.STL"/>
      </geometry>
    </collision>
    <visual>
      <origin rpy="0 0 0" xyz="0 0 0"/>
      <geometry>
        <mesh filename="cable.STL"/>
      </geometry>
    </visual>
    <inertial>
      <origin rpy="0 0 0" xyz="0 -0.125 0"/>
      <mass value="0.1"/>
      <inertia ixx="8e-05" ixy="0" ixz="0" iyy="2e-06" iyz="0.0" izz="8e-05"/>
    </inertial>
  </link>
  <!-- spring_part_a -->
  <!-- spring_part_a -->
  <!-- spring_part_a -->
  <link name="LF_spring_part_a">
    <collision>
      <origin rpy="0 0 0" xyz="0 0 0"/>
      <geometry>
        <mesh filename="spring_part_a.STL"/>
      </geometry>
    </collision>
    <visual>
      <origin rpy="0 0 0" xyz="0 0 0"/>
      <geometry>
        <mesh filename="spring_part_a.STL"/>
      </geometry>
    </visual>
    <inertial>
      <origin rpy="0 0 0" xyz="0 0 0"/>
      <mass value="0.05"/>
      <inertia ixx="1.2e-05" ixy="0" ixz="0" iyy="6.06e-05" iyz="5.08e-05" izz="0.0030174"/>
    </inertial>
  </link>
  <!-- spring_part_b -->
  <!-- spring_part_b -->
  <!-- spring_part_b -->
  <link name="LF_spring_part_b">
    <collision>
      <origin rpy="0 0 0" xyz="0 -0.03 0"/>
      <geometry>
        <mesh filename="spring_part_b.STL"/>
      </geometry>
    </collision>
    <visual>
      <origin rpy="0 0 0" xyz="0 -0.03 0"/>
      <geometry>
        <mesh filename="spring_part_b.STL"/>
      </geometry>
    </visual>
    <inertial>
      <origin rpy="0 0 0" xyz="0 0 0"/>
      <mass value="0.05"/>
      <inertia ixx="1.2e-05" ixy="0" ixz="0" iyy="1e-06" iyz="0" izz="1.2e-05"/>
    </inertial>
  </link>
  <!-- joint A -->
  <!-- joint A -->
  <!-- joint A -->
  <joint name="LF_joint_knee" type="revolute">
    <origin rpy="1.57 0 0" xyz="-0.3 -0.2 0.6"/>
    <parent link="body"/>
    <child link="LF_arm"/>
    <axis xyz="0 0 1"/>
    <dynamics damping="0.0"/>
    <limit effort="50" lower="-1.25" upper="1.25" velocity="8"/>
  </joint>
  <!-- joint B -->
  <!-- joint B -->
  <!-- joint B -->
  <joint name="LF_joint_hip" type="revolute">
    <origin rpy="1.57 0 0" xyz="-0.3 -0.216 0.6"/>
    <parent link="body"/>
    <child link="LF_femur"/>
    <axis xyz="0 0 1"/>
    <dynamics damping="0.0"/>
    <limit effort="50" lower="-1.25" upper="1.25" velocity="6"/>
  </joint>
  <!-- joint C -->
  <!-- joint C -->
  <!-- joint C -->
  <joint name="LF_joint_C" type="revolute">
    <origin rpy="0 0 0" xyz="0 -0.25 0"/>
    <parent link="LF_femur"/>
    <child link="LF_tibia"/>
    <axis xyz="0 0 1"/>
    <dynamics damping="0.0"/>
    <limit effort="100" lower="0.0" upper="1.57" velocity="100"/>
  </joint>
  <!-- joint D -->
  <!-- joint D -->
  <!-- joint D -->
  <joint name="LF_joint_D" type="revolute">
    <origin rpy="0 0 0.317475" xyz="0.09958 -0.3 0"/>
    <parent link="LF_tibia"/>
    <child link="LF_foot"/>
    <axis xyz="0 0 1"/>
    <dynamics damping="0.0"/>
    <limit effort="100" lower="-1.25" upper="1.25" velocity="100"/>
  </joint>
  <!-- joint E -->
  <!-- joint E -->
  <!-- joint E -->
  <joint name="LF_joint_E" type="continuous">
    <origin rpy="0 0 0" xyz="0.03536 -0.03536 0.0246"/>
    <parent link="LF_arm"/>
    <child link="LF_cable"/>
    <axis xyz="0 0 1"/>
    <dynamics damping="0.0"/>
    <limit effort="100" velocity="100"/>
  </joint>
  <!-- joint F -->
  <!-- joint F -->
  <!-- joint F -->
  <joint name="LF_joint_F" type="continuous">
    <origin rpy="0 0 0.608596" xyz="0.0514 -0.06 0.0089"/>
    <parent link="LF_tibia"/>
    <child link="LF_spring_part_a"/>
    <axis xyz="0 0 1"/>
    <dynamics damping="0.0"/>
    <limit effort="100" velocity="100"/>
  </joint>
  <!-- joint G -->
  <!-- joint G -->
  <!-- joint G -->
  <joint name="LF_joint_G" type="prismatic">
    <origin rpy="0 0 0" xyz="-0 -0.2 0"/>
    <parent link="LF_spring_part_a"/>
    <child link="LF_spring_part_b"/>
    <axis xyz="0 1 0"/>
    <dynamics damping="0.0"/>
    <limit effort="0" lower="-0.05" upper="0" velocity="0"/>
  </joint>
  <!-- joint G SDF -->
  <!-- joint G SDF -->
  <!-- joint G SDF -->
  <gazebo>
    <joint name="LF_joint_G_SDF" type="prismatic">
      <parent>LF_spring_part_a</parent>
      <child>LF_spring_part_b</child>
      <pose frame="">0 0 0 0 -0 0</pose>
      <axis>
        <xyz>0 1 0</xyz>
        <use_parent_model_frame>1</use_parent_model_frame>
        <limit>
          <lower>-0.05</lower>
          <upper>0</upper>
          <effort>0</effort>
          <velocity>0</velocity>
        </limit>
        <dynamics>
          <spring_reference>0</spring_reference>
          <spring_stiffness>26480</spring_stiffness>
          <damping>0.1</damping>
          <friction>0</friction>
        </dynamics>
      </axis>
    </joint>
  </gazebo>
  <!-- Gazebo Joint GA1  -->
  <!-- Gazebo Joint GA1  -->
  <!-- Gazebo Joint GA1  -->
  <gazebo>
    <joint name="LF_joint_GA1" type="revolute">
      <pose>0 -0.25 0 0 0 0</pose>
      <child>LF_cable</child>
      <parent>LF_tibia</parent>
      <axis>
        <xyz>0 0 1</xyz>
      </axis>
      <physics>
        <ode>
          <erp>0.5</erp>
          <!-- <cfm>0.1</cfm> -->
        </ode>
      </physics>
    </joint>
  </gazebo>
  <!-- Gazebo Joint GA2  -->
  <!-- Gazebo Joint GA2  -->
  <!-- Gazebo Joint GA2  -->
  <gazebo>
    <joint name="LF_joint_GA2" type="revolute">
      <pose>0 -0.025 0 0 0 0</pose>
      <child>LF_spring_part_b</child>
      <parent>LF_foot</parent>
      <axis>
        <xyz>0 0 1</xyz>
      </axis>
    </joint>
  </gazebo>
  <!-- Gazebo sensor A -->
  <!-- Gazebo sensor A -->
  <!-- Gazebo sensor A -->
  <gazebo reference="LF_joint_knee">
    <sensor name="LF_force_torque" type="force_torque">
      <always_on>true</always_on>
      <update_rate>1000</update_rate>
    </sensor>
  </gazebo>
  <!-- Gazebo sensor B -->
  <!-- Gazebo sensor B -->
  <!-- Gazebo sensor B -->
  <gazebo reference="LF_joint_hip">
    <sensor name="LF_force_torque" type="force_torque">
      <always_on>true</always_on>
      <update_rate>1000</update_rate>
    </sensor>
  </gazebo>
  <!-- Gazebo foot  -->
  <!-- Gazebo foot  -->
  <!-- Gazebo foot  -->
  <!-- <gazebo reference="${prefix1}${prefix2}_foot">
            <kp>100000</kp>
            <mu1>10</mu1>
            <mu2>10</mu2>
        </gazebo> -->
  <!-- Gazebo Joint TRAN1  -->
  <!-- Gazebo Joint TRAN1  -->
  <!-- Gazebo Joint TRAN1  -->
  <transmission name="LF_tran1">
    <type>transmission_interface/SimpleTransmission</type>
    <joint name="LF_joint_knee">
      <hardwareInterface>hardware_interface/EffortJointInterface</hardwareInterface>
    </joint>
    <actuator name="LF_motor1">
      <hardwareInterface>hardware_interface/EffortJointInterface</hardwareInterface>
      <mechanicalReduction>1</mechanicalReduction>
    </actuator>
  </transmission>
  <!-- Gazebo Joint TRAN2  -->
  <!-- Gazebo Joint TRAN2  -->
  <!-- Gazebo Joint TRAN2  -->
  <transmission name="LF_tran2">
    <type>transmission_interface/SimpleTransmission</type>
    <joint name="LF_joint_hip">
      <hardwareInterface>hardware_interface/EffortJointInterface</hardwareInterface>
    </joint>
    <actuator name="LF_motor2">
      <hardwareInterface>hardware_interface/EffortJointInterface</hardwareInterface>
      <mechanicalReduction>1</mechanicalReduction>
    </actuator>
  </transmission>
  <!-- arm -->
  <!-- arm -->
  <!-- arm -->
  <link name="LH_arm">
    <collision>
      <origin rpy="0 0 0" xyz="0 0 0"/>
      <geometry>
        <mesh filename="transmission_arm.STL"/>
      </geometry>
    </collision>
    <visual>
      <origin rpy="0 0 0" xyz="0 0 0"/>
      <geometry>
        <mesh filename="transmission_arm.STL"/>
      </geometry>
    </visual>
    <inertial>
      <origin rpy="0.0 0.0 0" xyz="0.001841 0.001845 0.000604"/>
      <mass value="0.243583"/>
      <inertia ixx="0.000238" ixy="-0.000143" ixz="0" iyy="0.000238" iyz="0" izz="0.000326"/>
    </inertial>
  </link>
  <!-- upper leg -->
  <!-- upper leg -->
  <!-- upper leg -->
  <link name="LH_femur">
    <collision>
      <origin rpy="0 0 0" xyz="0 0 0"/>
      <geometry>
        <mesh filename="femur.STL"/>
      </geometry>
    </collision>
    <visual>
      <origin rpy="0 0 0" xyz="0 0 0"/>
      <geometry>
        <mesh filename="femur.STL"/>
      </geometry>
    </visual>
    <inertial>
      <origin rpy="0 0 0" xyz="0 -0.1089928 0.0013804"/>
      <mass value="0.321675"/>
      <inertia ixx="0.0030216" ixy="0.0" ixz="0.0" iyy="6.06e-05" iyz="5.08e-05" izz="0.0030174"/>
    </inertial>
  </link>
  <!-- lower leg -->
  <!-- lower leg -->
  <!-- lower leg -->
  <link name="LH_tibia">
    <collision>
      <origin rpy="0 0 0" xyz="0 0 0"/>
      <geometry>
        <mesh filename="tibia.STL"/>
      </geometry>
    </collision>
    <visual>
      <origin rpy="0 0 0" xyz="0 0 0"/>
      <geometry>
        <mesh filename="tibia.STL"/>
      </geometry>
    </visual>
    <inertial>
      <origin rpy="0.0 0.0 0" xyz="0.0343235 -0.1131727 -0.0003377"/>
      <mass value="0.583068"/>
      <inertia ixx="0.0069971" ixy="-0.0025079" ixz="-4.13e-05" iyy="0.00113" iyz="0.0001357" izz="0.0080248"/>
    </inertial>
  </link>
  <!-- foot -->
  <!-- foot -->
  <!-- foot -->
  <link name="LH_foot">
    <collision>
      <origin rpy="0 0 0" xyz="0 0 0"/>
      <geometry>
        <mesh filename="foot.STL"/>
      </geometry>
    </collision>
    <visual>
      <origin rpy="0 0 0" xyz="0 0 0"/>
      <geometry>
        <mesh filename="foot.STL"/>
      </geometry>
    </visual>
    <inertial>
      <origin rpy="0 0 0" xyz="0 0 0"/>
      <mass value="0.185259"/>
      <inertia ixx="3.9e-05" ixy="0.000114" ixz="1.4e-05" iyy="0.000946" iyz="3e-06" izz="0.000974"/>
    </inertial>
  </link>
  <!-- foot -->
  <!-- foot -->
  <!-- foot -->
  <gazebo reference="LH_foot">
    <collision>
      <surface>
        <bounce>
          <restitution_coefficient>0</restitution_coefficient>
          <threshold>1e+06</threshold>
        </bounce>
        <friction>
          <torsional>
            <coefficient>1.0</coefficient>
          </torsional>
          <ode>
            <mu>1.2</mu>
            <mu2>1.2</mu2>
          </ode>
          <bullet>
            <rolling_friction>1.0</rolling_friction>
            <friction2>1.2</friction2>
          </bullet>
        </friction>
        <contact>
          <ode>
            <kp>300000.0</kp>
            <kd>1000.0</kd>
          </ode>
          <bullet>
            <kp>300000.0</kp>
            <kd>1000.0</kd>
          </bullet>
        </contact>
      </surface>
    </collision>
  </gazebo>
  <!-- cable -->
  <!-- cable -->
  <!-- cable -->
  <link name="LH_cable">
    <collision>
      <origin rpy="0 0 0" xyz="0 0 0"/>
      <geometry>
        <mesh filename="cable.STL"/>
      </geometry>
    </collision>
    <visual>
      <origin rpy="0 0 0" xyz="0 0 0"/>
      <geometry>
        <mesh filename="cable.STL"/>
      </geometry>
    </visual>
    <inertial>
      <origin rpy="0 0 0" xyz="0 -0.125 0"/>
      <mass value="0.1"/>
      <inertia ixx="8e-05" ixy="0" ixz="0" iyy="2e-06" iyz="0.0" izz="8e-05"/>
    </inertial>
  </link>
  <!-- spring_part_a -->
  <!-- spring_part_a -->
  <!-- spring_part_a -->
  <link name="LH_spring_part_a">
    <collision>
      <origin rpy="0 0 0" xyz="0 0 0"/>
      <geometry>
        <mesh filename="spring_part_a.STL"/>
      </geometry>
    </collision>
    <visual>
      <origin rpy="0 0 0" xyz="0 0 0"/>
      <geometry>
        <mesh filename="spring_part_a.STL"/>
      </geometry>
    </visual>
    <inertial>
      <origin rpy="0 0 0" xyz="0 0 0"/>
      <mass value="0.05"/>
      <inertia ixx="1.2e-05" ixy="0" ixz="0" iyy="6.06e-05" iyz="5.08e-05" izz="0.0030174"/>
    </inertial>
  </link>
  <!-- spring_part_b -->
  <!-- spring_part_b -->
  <!-- spring_part_b -->
  <link name="LH_spring_part_b">
    <collision>
      <origin rpy="0 0 0" xyz="0 -0.03 0"/>
      <geometry>
        <mesh filename="spring_part_b.STL"/>
      </geometry>
    </collision>
    <visual>
      <origin rpy="0 0 0" xyz="0 -0.03 0"/>
      <geometry>
        <mesh filename="spring_part_b.STL"/>
      </geometry>
    </visual>
    <inertial>
      <origin rpy="0 0 0" xyz="0 0 0"/>
      <mass value="0.05"/>
      <inertia ixx="1.2e-05" ixy="0" ixz="0" iyy="1e-06" iyz="0" izz="1.2e-05"/>
    </inertial>
  </link>
  <!-- joint A -->
  <!-- joint A -->
  <!-- joint A -->
  <joint name="LH_joint_knee" type="revolute">
    <origin rpy="1.57 0 0" xyz="0.28 -0.2 0.6"/>
    <parent link="body"/>
    <child link="LH_arm"/>
    <axis xyz="0 0 1"/>
    <dynamics damping="0.0"/>
    <limit effort="50" lower="-1.25" upper="1.25" velocity="8"/>
  </joint>
  <!-- joint B -->
  <!-- joint B -->
  <!-- joint B -->
  <joint name="LH_joint_hip" type="revolute">
    <origin rpy="1.57 0 0" xyz="0.28 -0.216 0.6"/>
    <parent link="body"/>
    <child link="LH_femur"/>
    <axis xyz="0 0 1"/>
    <dynamics damping="0.0"/>
    <limit effort="50" lower="-1.25" upper="1.25" velocity="6"/>
  </joint>
  <!-- joint C -->
  <!-- joint C -->
  <!-- joint C -->
  <joint name="LH_joint_C" type="revolute">
    <origin rpy="0 0 0" xyz="0 -0.25 0"/>
    <parent link="LH_femur"/>
    <child link="LH_tibia"/>
    <axis xyz="0 0 1"/>
    <dynamics damping="0.0"/>
    <limit effort="100" lower="0.0" upper="1.57" velocity="100"/>
  </joint>
  <!-- joint D -->
  <!-- joint D -->
  <!-- joint D -->
  <joint name="LH_joint_D" type="revolute">
    <origin rpy="0 0 0.317475" xyz="0.09958 -0.3 0"/>
    <parent link="LH_tibia"/>
    <child link="LH_foot"/>
    <axis xyz="0 0 1"/>
    <dynamics damping="0.0"/>
    <limit effort="100" lower="-1.25" upper="1.25" velocity="100"/>
  </joint>
  <!-- joint E -->
  <!-- joint E -->
  <!-- joint E -->
  <joint name="LH_joint_E" type="continuous">
    <origin rpy="0 0 0" xyz="0.03536 -0.03536 0.0246"/>
    <parent link="LH_arm"/>
    <child link="LH_cable"/>
    <axis xyz="0 0 1"/>
    <dynamics damping="0.0"/>
    <limit effort="100" velocity="100"/>
  </joint>
  <!-- joint F -->
  <!-- joint F -->
  <!-- joint F -->
  <joint name="LH_joint_F" type="continuous">
    <origin rpy="0 0 0.608596" xyz="0.0514 -0.06 0.0089"/>
    <parent link="LH_tibia"/>
    <child link="LH_spring_part_a"/>
    <axis xyz="0 0 1"/>
    <dynamics damping="0.0"/>
    <limit effort="100" velocity="100"/>
  </joint>
  <!-- joint G -->
  <!-- joint G -->
  <!-- joint G -->
  <joint name="LH_joint_G" type="prismatic">
    <origin rpy="0 0 0" xyz="-0 -0.2 0"/>
    <parent link="LH_spring_part_a"/>
    <child link="LH_spring_part_b"/>
    <axis xyz="0 1 0"/>
    <dynamics damping="0.0"/>
    <limit effort="0" lower="-0.05" upper="0" velocity="0"/>
  </joint>
  <!-- joint G SDF -->
  <!-- joint G SDF -->
  <!-- joint G SDF -->
  <gazebo>
    <joint name="LH_joint_G_SDF" type="prismatic">
      <parent>LH_spring_part_a</parent>
      <child>LH_spring_part_b</child>
      <pose frame="">0 0 0 0 -0 0</pose>
      <axis>
        <xyz>0 1 0</xyz>
        <use_parent_model_frame>1</use_parent_model_frame>
        <limit>
          <lower>-0.05</lower>
          <upper>0</upper>
          <effort>0</effort>
          <velocity>0</velocity>
        </limit>
        <dynamics>
          <spring_reference>0</spring_reference>
          <spring_stiffness>26480</spring_stiffness>
          <damping>0.1</damping>
          <friction>0</friction>
        </dynamics>
      </axis>
    </joint>
  </gazebo>
  <!-- Gazebo Joint GA1  -->
  <!-- Gazebo Joint GA1  -->
  <!-- Gazebo Joint GA1  -->
  <gazebo>
    <joint name="LH_joint_GA1" type="revolute">
      <pose>0 -0.25 0 0 0 0</pose>
      <child>LH_cable</child>
      <parent>LH_tibia</parent>
      <axis>
        <xyz>0 0 1</xyz>
      </axis>
      <physics>
        <ode>
          <erp>0.5</erp>
          <!-- <cfm>0.1</cfm> -->
        </ode>
      </physics>
    </joint>
  </gazebo>
  <!-- Gazebo Joint GA2  -->
  <!-- Gazebo Joint GA2  -->
  <!-- Gazebo Joint GA2  -->
  <gazebo>
    <joint name="LH_joint_GA2" type="revolute">
      <pose>0 -0.025 0 0 0 0</pose>
      <child>LH_spring_part_b</child>
      <parent>LH_foot</parent>
      <axis>
        <xyz>0 0 1</xyz>
      </axis>
    </joint>
  </gazebo>
  <!-- Gazebo sensor A -->
  <!-- Gazebo sensor A -->
  <!-- Gazebo sensor A -->
  <gazebo reference="LH_joint_knee">
    <sensor name="LH_force_torque" type="force_torque">
      <always_on>true</always_on>
      <update_rate>1000</update_rate>
    </sensor>
  </gazebo>
  <!-- Gazebo sensor B -->
  <!-- Gazebo sensor B -->
  <!-- Gazebo sensor B -->
  <gazebo reference="LH_joint_hip">
    <sensor name="LH_force_torque" type="force_torque">
      <always_on>true</always_on>
      <update_rate>1000</update_rate>
    </sensor>
  </gazebo>
  <!-- Gazebo foot  -->
  <!-- Gazebo foot  -->
  <!-- Gazebo foot  -->
  <!-- <gazebo reference="${prefix1}${prefix2}_foot">
            <kp>100000</kp>
            <mu1>10</mu1>
            <mu2>10</mu2>
        </gazebo> -->
  <!-- Gazebo Joint TRAN1  -->
  <!-- Gazebo Joint TRAN1  -->
  <!-- Gazebo Joint TRAN1  -->
  <transmission name="LH_tran1">
    <type>transmission_interface/SimpleTransmission</type>
    <joint name="LH_joint_knee">
      <hardwareInterface>hardware_interface/EffortJointInterface</hardwareInterface>
    </joint>
    <actuator name="LH_motor1">
      <hardwareInterface>hardware_interface/EffortJointInterface</hardwareInterface>
      <mechanicalReduction>1</mechanicalReduction>
    </actuator>
  </transmission>
  <!-- Gazebo Joint TRAN2  -->
  <!-- Gazebo Joint TRAN2  -->
  <!-- Gazebo Joint TRAN2  -->
  <transmission name="LH_tran2">
    <type>transmission_interface/SimpleTransmission</type>
    <joint name="LH_joint_hip">
      <hardwareInterface>hardware_interface/EffortJointInterface</hardwareInterface>
    </joint>
    <actuator name="LH_motor2">
      <hardwareInterface>hardware_interface/EffortJointInterface</hardwareInterface>
      <mechanicalReduction>1</mechanicalReduction>
    </actuator>
  </transmission>
</robot>
